Workbook

Sheet Base de dados
A1: Cliente | B1: CD_USU | C1: Nota | D1: Nota válida | E1: Carteira válida | F1: Limite 2 avaliações | G1: Válido para apuração
A2: 1 | B2: A | C2: 1 | D2: =IF(AND(C2>0,C2<=5),"SIM","NÃO") -> SIM | E2: =IF(OR(B2="A",B2="B",B2="C",B2="E"),"SIM","NÃO") -> SIM | F2: =IF(COUNTIFS($A$2:A2,A2,$B$2:B2,B2)<=2,"SIM","NÃO") -> SIM | G2: =IF(AND(D2="SIM",E2="SIM",F2="SIM"),"SIM","NÃO") -> SIM
A3: 2 | B3: A | C3: 1 | D3: =IF(AND(C3>0,C3<=5),"SIM","NÃO") -> SIM | E3: =IF(OR(B3="A",B3="B",B3="C",B3="E"),"SIM","NÃO") -> SIM | F3: =IF(COUNTIFS($A$2:A3,A3,$B$2:B3,B3)<=2,"SIM","NÃO") -> SIM | G3: =IF(AND(D3="SIM",E3="SIM",F3="SIM"),"SIM","NÃO") -> SIM
A4: 3 | B4: A | C4: 1 | D4: =IF(AND(C4>0,C4<=5),"SIM","NÃO") -> SIM | E4: =IF(OR(B4="A",B4="B",B4="C",B4="E"),"SIM","NÃO") -> SIM | F4: =IF(COUNTIFS($A$2:A4,A4,$B$2:B4,B4)<=2,"SIM","NÃO") -> SIM | G4: =IF(AND(D4="SIM",E4="SIM",F4="SIM"),"SIM","NÃO") -> SIM
A5: 4 | B5: A | C5: 1 | D5: =IF(AND(C5>0,C5<=5),"SIM","NÃO") -> SIM | E5: =IF(OR(B5="A",B5="B",B5="C",B5="E"),"SIM","NÃO") -> SIM | F5: =IF(COUNTIFS($A$2:A5,A5,$B$2:B5,B5)<=2,"SIM","NÃO") -> SIM | G5: =IF(AND(D5="SIM",E5="SIM",F5="SIM"),"SIM","NÃO") -> SIM
A6: 5 | B6: B | C6: 5 | D6: =IF(AND(C6>0,C6<=5),"SIM","NÃO") -> SIM | E6: =IF(OR(B6="A",B6="B",B6="C",B6="E"),"SIM","NÃO") -> SIM | F6: =IF(COUNTIFS($A$2:A6,A6,$B$2:B6,B6)<=2,"SIM","NÃO") -> SIM | G6: =IF(AND(D6="SIM",E6="SIM",F6="SIM"),"SIM","NÃO") -> SIM
A7: 6 | B7: B | C7: 5 | D7: =IF(AND(C7>0,C7<=5),"SIM","NÃO") -> SIM | E7: =IF(OR(B7="A",B7="B",B7="C",B7="E"),"SIM","NÃO") -> SIM | F7: =IF(COUNTIFS($A$2:A7,A7,$B$2:B7,B7)<=2,"SIM","NÃO") -> SIM | G7: =IF(AND(D7="SIM",E7="SIM",F7="SIM"),"SIM","NÃO") -> SIM
A8: 7 | B8: B | C8: 5 | D8: =IF(AND(C8>0,C8<=5),"SIM","NÃO") -> SIM | E8: =IF(OR(B8="A",B8="B",B8="C",B8="E"),"SIM","NÃO") -> SIM | F8: =IF(COUNTIFS($A$2:A8,A8,$B$2:B8,B8)<=2,"SIM","NÃO") -> SIM | G8: =IF(AND(D8="SIM",E8="SIM",F8="SIM"),"SIM","NÃO") -> SIM
A9: 8 | B9: B | C9: 4 | D9: =IF(AND(C9>0,C9<=5),"SIM","NÃO") -> SIM | E9: =IF(OR(B9="A",B9="B",B9="C",B9="E"),"SIM","NÃO") -> SIM | F9: =IF(COUNTIFS($A$2:A9,A9,$B$2:B9,B9)<=2,"SIM","NÃO") -> SIM | G9: =IF(AND(D9="SIM",E9="SIM",F9="SIM"),"SIM","NÃO") -> SIM
A10: 9 | B10: C | C10: 5 | D10: =IF(AND(C10>0,C10<=5),"SIM","NÃO") -> SIM | E10: =IF(OR(B10="A",B10="B",B10="C",B10="E"),"SIM","NÃO") -> SIM | F10: =IF(COUNTIFS($A$2:A10,A10,$B$2:B10,B10)<=2,"SIM","NÃO") -> SIM | G10: =IF(AND(D10="SIM",E10="SIM",F10="SIM"),"SIM","NÃO") -> SIM
A11: 10 | B11: C | C11: 3 | D11: =IF(AND(C11>0,C11<=5),"SIM","NÃO") -> SIM | E11: =IF(OR(B11="A",B11="B",B11="C",B11="E"),"SIM","NÃO") -> SIM | F11: =IF(COUNTIFS($A$2:A11,A11,$B$2:B11,B11)<=2,"SIM","NÃO") -> SIM | G11: =IF(AND(D11="SIM",E11="SIM",F11="SIM"),"SIM","NÃO") -> SIM
A12: 11 | B12: A | C12: 3 | D12: =IF(AND(C12>0,C12<=5),"SIM","NÃO") -> SIM | E12: =IF(OR(B12="A",B12="B",B12="C",B12="E"),"SIM","NÃO") -> SIM | F12: =IF(COUNTIFS($A$2:A12,A12,$B$2:B12,B12)<=2,"SIM","NÃO") -> SIM | G12: =IF(AND(D12="SIM",E12="SIM",F12="SIM"),"SIM","NÃO") -> SIM
A13: 12 | B13: A | C13: 2 | D13: =IF(AND(C13>0,C13<=5),"SIM","NÃO") -> SIM | E13: =IF(OR(B13="A",B13="B",B13="C",B13="E"),"SIM","NÃO") -> SIM | F13: =IF(COUNTIFS($A$2:A13,A13,$B$2:B13,B13)<=2,"SIM","NÃO") -> SIM | G13: =IF(AND(D13="SIM",E13="SIM",F13="SIM"),"SIM","NÃO") -> SIM
... A55: 54 | B55: D | C55: 3 | D55: =IF(AND(C55>0,C55<=5),"SIM","NÃO") -> SIM | E55: =IF(OR(B55="A",B55="B",B55="C",B55="E"),"SIM","NÃO") -> NÃO | F55: =IF(COUNTIFS($A$2:A55,A55,$B$2:B55,B55)<=2,"SIM","NÃO") -> SIM | G55: =IF(AND(D55="SIM",E55="SIM",F55="SIM"),"SIM","NÃO") -> NÃO
A56: 55 | B56: D | D56: =IF(AND(C56>0,C56<=5),"SIM","NÃO") -> NÃO | E56: =IF(OR(B56="A",B56="B",B56="C",B56="E"),"SIM","NÃO") -> NÃO | F56: =IF(COUNTIFS($A$2:A56,A56,$B$2:B56,B56)<=2,"SIM","NÃO") -> SIM | G56: =IF(AND(D56="SIM",E56="SIM",F56="SIM"),"SIM","NÃO") -> NÃO
A57: 56 | B57: D | C57: 2 | D57: =IF(AND(C57>0,C57<=5),"SIM","NÃO") -> SIM | E57: =IF(OR(B57="A",B57="B",B57="C",B57="E"),"SIM","NÃO") -> NÃO | F57: =IF(COUNTIFS($A$2:A57,A57,$B$2:B57,B57)<=2,"SIM","NÃO") -> SIM | G57: =IF(AND(D57="SIM",E57="SIM",F57="SIM"),"SIM","NÃO") -> NÃO
A58: 57 | B58: D | C58: 3 | D58: =IF(AND(C58>0,C58<=5),"SIM","NÃO") -> SIM | E58: =IF(OR(B58="A",B58="B",B58="C",B58="E"),"SIM","NÃO") -> NÃO | F58: =IF(COUNTIFS($A$2:A58,A58,$B$2:B58,B58)<=2,"SIM","NÃO") -> SIM | G58: =IF(AND(D58="SIM",E58="SIM",F58="SIM"),"SIM","NÃO") -> NÃO
A59: 58 | B59: D | C59: 4 | D59: =IF(AND(C59>0,C59<=5),"SIM","NÃO") -> SIM | E59: =IF(OR(B59="A",B59="B",B59="C",B59="E"),"SIM","NÃO") -> NÃO | F59: =IF(COUNTIFS($A$2:A59,A59,$B$2:B59,B59)<=2,"SIM","NÃO") -> SIM | G59: =IF(AND(D59="SIM",E59="SIM",F59="SIM"),"SIM","NÃO") -> NÃO
A60: 59 | B60: D | C60: 1 | D60: =IF(AND(C60>0,C60<=5),"SIM","NÃO") -> SIM | E60: =IF(OR(B60="A",B60="B",B60="C",B60="E"),"SIM","NÃO") -> NÃO | F60: =IF(COUNTIFS($A$2:A60,A60,$B$2:B60,B60)<=2,"SIM","NÃO") -> SIM | G60: =IF(AND(D60="SIM",E60="SIM",F60="SIM"),"SIM","NÃO") -> NÃO
A61: 60 | B61: D | C61: 3 | D61: =IF(AND(C61>0,C61<=5),"SIM","NÃO") -> SIM | E61: =IF(OR(B61="A",B61="B",B61="C",B61="E"),"SIM","NÃO") -> NÃO | F61: =IF(COUNTIFS($A$2:A61,A61,$B$2:B61,B61)<=2,"SIM","NÃO") -> SIM | G61: =IF(AND(D61="SIM",E61="SIM",F61="SIM"),"SIM","NÃO") -> NÃO
A62: 61 | B62: D | C62: 2 | D62: =IF(AND(C62>0,C62<=5),"SIM","NÃO") -> SIM | E62: =IF(OR(B62="A",B62="B",B62="C",B62="E"),"SIM","NÃO") -> NÃO | F62: =IF(COUNTIFS($A$2:A62,A62,$B$2:B62,B62)<=2,"SIM","NÃO") -> SIM | G62: =IF(AND(D62="SIM",E62="SIM",F62="SIM"),"SIM","NÃO") -> NÃO
A63: 62 | B63: D | C63: 4 | D63: =IF(AND(C63>0,C63<=5),"SIM","NÃO") -> SIM | E63: =IF(OR(B63="A",B63="B",B63="C",B63="E"),"SIM","NÃO") -> NÃO | F63: =IF(COUNTIFS($A$2:A63,A63,$B$2:B63,B63)<=2,"SIM","NÃO") -> SIM | G63: =IF(AND(D63="SIM",E63="SIM",F63="SIM"),"SIM","NÃO") -> NÃO
A64: 63 | B64: D | C64: 5 | D64: =IF(AND(C64>0,C64<=5),"SIM","NÃO") -> SIM | E64: =IF(OR(B64="A",B64="B",B64="C",B64="E"),"SIM","NÃO") -> NÃO | F64: =IF(COUNTIFS($A$2:A64,A64,$B$2:B64,B64)<=2,"SIM","NÃO") -> SIM | G64: =IF(AND(D64="SIM",E64="SIM",F64="SIM"),"SIM","NÃO") -> NÃO
A65: 64 | B65: D | C65: 3 | D65: =IF(AND(C65>0,C65<=5),"SIM","NÃO") -> SIM | E65: =IF(OR(B65="A",B65="B",B65="C",B65="E"),"SIM","NÃO") -> NÃO | F65: =IF(COUNTIFS($A$2:A65,A65,$B$2:B65,B65)<=2,"SIM","NÃO") -> SIM | G65: =IF(AND(D65="SIM",E65="SIM",F65="SIM"),"SIM","NÃO") -> NÃO
A66: 65 | B66: A | C66: 2 | D66: =IF(AND(C66>0,C66<=5),"SIM","NÃO") -> SIM | E66: =IF(OR(B66="A",B66="B",B66="C",B66="E"),"SIM","NÃO") -> SIM | F66: =IF(COUNTIFS($A$2:A66,A66,$B$2:B66,B66)<=2,"SIM","NÃO") -> SIM | G66: =IF(AND(D66="SIM",E66="SIM",F66="SIM"),"SIM","NÃO") -> SIM
A67: 66 | B67: A | C67: 1 | D67: =IF(AND(C67>0,C67<=5),"SIM","NÃO") -> SIM | E67: =IF(OR(B67="A",B67="B",B67="C",B67="E"),"SIM","NÃO") -> SIM | F67: =IF(COUNTIFS($A$2:A67,A67,$B$2:B67,B67)<=2,"SIM","NÃO") -> SIM | G67: =IF(AND(D67="SIM",E67="SIM",F67="SIM"),"SIM","NÃO") -> SIM
A68: 67 | B68: A | C68: 1 | D68: =IF(AND(C68>0,C68<=5),"SIM","NÃO") -> SIM | E68: =IF(OR(B68="A",B68="B",B68="C",B68="E"),"SIM","NÃO") -> SIM | F68: =IF(COUNTIFS($A$2:A68,A68,$B$2:B68,B68)<=2,"SIM","NÃO") -> SIM | G68: =IF(AND(D68="SIM",E68="SIM",F68="SIM"),"SIM","NÃO") -> SIM
... A91: 90 | B91: E | C91: 1 | D91: =IF(AND(C91>0,C91<=5),"SIM","NÃO") -> SIM | E91: =IF(OR(B91="A",B91="B",B91="C",B91="E"),"SIM","NÃO") -> SIM | F91: =IF(COUNTIFS($A$2:A91,A91,$B$2:B91,B91)<=2,"SIM","NÃO") -> SIM | G91: =IF(AND(D91="SIM",E91="SIM",F91="SIM"),"SIM","NÃO") -> SIM
A92: 91 | B92: E | D92: =IF(AND(C92>0,C92<=5),"SIM","NÃO") -> NÃO | E92: =IF(OR(B92="A",B92="B",B92="C",B92="E"),"SIM","NÃO") -> SIM | F92: =IF(COUNTIFS($A$2:A92,A92,$B$2:B92,B92)<=2,"SIM","NÃO") -> SIM | G92: =IF(AND(D92="SIM",E92="SIM",F92="SIM"),"SIM","NÃO") -> NÃO
A93: 92 | B93: E | C93: 3 | D93: =IF(AND(C93>0,C93<=5),"SIM","NÃO") -> SIM | E93: =IF(OR(B93="A",B93="B",B93="C",B93="E"),"SIM","NÃO") -> SIM | F93: =IF(COUNTIFS($A$2:A93,A93,$B$2:B93,B93)<=2,"SIM","NÃO") -> SIM | G93: =IF(AND(D93="SIM",E93="SIM",F93="SIM"),"SIM","NÃO") -> SIM
A94: 93 | B94: E | C94: 0 | D94: =IF(AND(C94>0,C94<=5),"SIM","NÃO") -> NÃO | E94: =IF(OR(B94="A",B94="B",B94="C",B94="E"),"SIM","NÃO") -> SIM | F94: =IF(COUNTIFS($A$2:A94,A94,$B$2:B94,B94)<=2,"SIM","NÃO") -> SIM | G94: =IF(AND(D94="SIM",E94="SIM",F94="SIM"),"SIM","NÃO") -> NÃO
A95: 94 | B95: E | C95: 4 | D95: =IF(AND(C95>0,C95<=5),"SIM","NÃO") -> SIM | E95: =IF(OR(B95="A",B95="B",B95="C",B95="E"),"SIM","NÃO") -> SIM | F95: =IF(COUNTIFS($A$2:A95,A95,$B$2:B95,B95)<=2,"SIM","NÃO") -> SIM | G95: =IF(AND(D95="SIM",E95="SIM",F95="SIM"),"SIM","NÃO") -> SIM
A96: 95 | B96: E | C96: 3 | D96: =IF(AND(C96>0,C96<=5),"SIM","NÃO") -> SIM | E96: =IF(OR(B96="A",B96="B",B96="C",B96="E"),"SIM","NÃO") -> SIM | F96: =IF(COUNTIFS($A$2:A96,A96,$B$2:B96,B96)<=2,"SIM","NÃO") -> SIM | G96: =IF(AND(D96="SIM",E96="SIM",F96="SIM"),"SIM","NÃO") -> SIM
A97: 96 | B97: E | C97: 5 | D97: =IF(AND(C97>0,C97<=5),"SIM","NÃO") -> SIM | E97: =IF(OR(B97="A",B97="B",B97="C",B97="E"),"SIM","NÃO") -> SIM | F97: =IF(COUNTIFS($A$2:A97,A97,$B$2:B97,B97)<=2,"SIM","NÃO") -> SIM | G97: =IF(AND(D97="SIM",E97="SIM",F97="SIM"),"SIM","NÃO") -> SIM
A98: 97 | B98: E | C98: 4 | D98: =IF(AND(C98>0,C98<=5),"SIM","NÃO") -> SIM | E98: =IF(OR(B98="A",B98="B",B98="C",B98="E"),"SIM","NÃO") -> SIM | F98: =IF(COUNTIFS($A$2:A98,A98,$B$2:B98,B98)<=2,"SIM","NÃO") -> SIM | G98: =IF(AND(D98="SIM",E98="SIM",F98="SIM"),"SIM","NÃO") -> SIM
A99: 98 | B99: E | C99: 5 | D99: =IF(AND(C99>0,C99<=5),"SIM","NÃO") -> SIM | E99: =IF(OR(B99="A",B99="B",B99="C",B99="E"),"SIM","NÃO") -> SIM | F99: =IF(COUNTIFS($A$2:A99,A99,$B$2:B99,B99)<=2,"SIM","NÃO") -> SIM | G99: =IF(AND(D99="SIM",E99="SIM",F99="SIM"),"SIM","NÃO") -> SIM
A100: 99 | B100: E | C100: 2 | D100: =IF(AND(C100>0,C100<=5),"SIM","NÃO") -> SIM | E100: =IF(OR(B100="A",B100="B",B100="C",B100="E"),"SIM","NÃO") -> SIM | F100: =IF(COUNTIFS($A$2:A100,A100,$B$2:B100,B100)<=2,"SIM","NÃO") -> SIM | G100: =IF(AND(D100="SIM",E100="SIM",F100="SIM"),"SIM","NÃO") -> SIM
A101: 100 | B101: E | C101: 1 | D101: =IF(AND(C101>0,C101<=5),"SIM","NÃO") -> SIM | E101: =IF(OR(B101="A",B101="B",B101="C",B101="E"),"SIM","NÃO") -> SIM | F101: =IF(COUNTIFS($A$2:A101,A101,$B$2:B101,B101)<=2,"SIM","NÃO") -> SIM | G101: =IF(AND(D101="SIM",E101="SIM",F101="SIM"),"SIM","NÃO") -> SIM
A102: 29 | B102: B | C102: 5 | D102: =IF(AND(C102>0,C102<=5),"SIM","NÃO") -> SIM | E102: =IF(OR(B102="A",B102="B",B102="C",B102="E"),"SIM","NÃO") -> SIM | F102: =IF(COUNTIFS($A$2:A102,A102,$B$2:B102,B102)<=2,"SIM","NÃO") -> SIM | G102: =IF(AND(D102="SIM",E102="SIM",F102="SIM"),"SIM","NÃO") -> SIM
A103: 29 | B103: B | C103: 5 | D103: =IF(AND(C103>0,C103<=5),"SIM","NÃO") -> SIM | E103: =IF(OR(B103="A",B103="B",B103="C",B103="E"),"SIM","NÃO") -> SIM | F103: =IF(COUNTIFS($A$2:A103,A103,$B$2:B103,B103)<=2,"SIM","NÃO") -> NÃO | G103: =IF(AND(D103="SIM",E103="SIM",F103="SIM"),"SIM","NÃO") -> NÃO
...

Sheet Resultados por carteira
A1: Carteira | B1: CD_USU | C1: Média | D1: Pontuação da Média | E1: Quantidade de avaliações | F1: Pontuação por quantidade | G1: Realizado
A2: 1 | B2: A | C2: =AVERAGEIFS('Base de dados'!C:C,'Base de dados'!B:B,B2,'Base de dados'!G:G,"SIM") -> 1.5121951 | D2: =IF(C2<=1,150,IF(C2<=2,300,IF(C2<=3,450,IF(C2<=4,600,750)))) -> 300 | E2: =COUNTIFS('Base de dados'!B:B,B2,'Base de dados'!G:G,"SIM") -> 41 | F2: =IF(E2<=5,150,IF(E2<=10,300,IF(E2<=11,450,IF(E2<=13,600,750)))) -> 750 | G2: =SUM(D2,F2) -> 1050
A3: 2 | B3: E | C3: =AVERAGEIFS('Base de dados'!C:C,'Base de dados'!B:B,B3,'Base de dados'!G:G,"SIM") -> 3.2 | D3: =IF(C3<=1,150,IF(C3<=2,300,IF(C3<=3,450,IF(C3<=4,600,750)))) -> 600 | E3: =COUNTIFS('Base de dados'!B:B,B3,'Base de dados'!G:G,"SIM") -> 30 | F3: =IF(E3<=5,150,IF(E3<=10,300,IF(E3<=11,450,IF(E3<=13,600,750)))) -> 750 | G3: =SUM(D3,F3) -> 1350
A4: 3 | B4: B | C4: =AVERAGEIFS('Base de dados'!C:C,'Base de dados'!B:B,B4,'Base de dados'!G:G,"SIM") -> 4.7241379 | D4: =IF(C4<=1,150,IF(C4<=2,300,IF(C4<=3,450,IF(C4<=4,600,750)))) -> 750 | E4: =COUNTIFS('Base de dados'!B:B,B4,'Base de dados'!G:G,"SIM") -> 29 | F4: =IF(E4<=5,150,IF(E4<=10,300,IF(E4<=11,450,IF(E4<=13,600,750)))) -> 750 | G4: =SUM(D4,F4) -> 1500
A5: 4 | B5: C | C5: =AVERAGEIFS('Base de dados'!C:C,'Base de dados'!B:B,B5,'Base de dados'!G:G,"SIM") -> 2.9285714 | D5: =IF(C5<=1,150,IF(C5<=2,300,IF(C5<=3,450,IF(C5<=4,600,750)))) -> 450 | E5: =COUNTIFS('Base de dados'!B:B,B5,'Base de dados'!G:G,"SIM") -> 42 | F5: =IF(E5<=5,150,IF(E5<=10,300,IF(E5<=11,450,IF(E5<=13,600,750)))) -> 750 | G5: =SUM(D5,F5) -> 1200
A6: 5 | B6: D | C6: Não se aplica | D6: Não elegível | E6: Não elegível | F6: Não elegível | G6: Não elegível

Sheet Resultado da agência
A1: Carteiras válidas consideradas | B1: Realizado pela agência
A2: 4 | B2: =AVERAGE('Resultados por carteira'!G2:G5) -> 1275
